<?xml version="1.0"?>
<robot name="traxster">

    <material name="blue">
        <color rgba="0 0 0.8 1"/>
    </material>

    <material name="black">
        <color rgba="0 0 0 1"/>
    </material>

    <link name="base_footprint">
	    <visual>
	        <origin rpy="0 0 0" xyz="0 0 0"/>
	        <geometry>
		        <box size="0.001 0.001 0.001"/>
	        </geometry>
	    </visual>
    </link>

    <gazebo reference="base_footprint">
	    <turnGravityOff>false</turnGravityOff>
	</gazebo>

    <joint name="base_footprint_joint" type="fixed">
        <origin rpy="0 0 0" xyz="0 0 0.2"/>
        <parent link="base_footprint"/>
        <child link="base_link"/>
	</joint>

    <link name="base_link">
        <inertial>
            <mass value="3"/>
            <origin xyz="0 0 0"/>
            <inertia ixx="0.0282916666667" ixy="0" ixz="0" iyy="0.0282916666667" iyz="0" izz="0.05625"/>
        </inertial>
        <visual>
            <geometry>
                <box size="0.22606 0.11360 0.047731"/>
            </geometry>
            <origin xyz="0 0 0" xyz="0 0 0"/>
            <material name="blue"/>
        </visual>
        <collision>
            <geometry>
                <box size="0.22606 0.11360 0.047731"/>
            </geometry>
            <origin xyz="0 0 0" xyz="0 0 0"/>
            <material name="blue"/>
        </collision>
    </link>

    <gazebo reference="base_link">
        <turnGravityOff>false</turnGravityOff>
    </gazebo>

    <link name="right_track_1">
        <inertial>
            <mass value="1"/>
		    <inertia ixx="1.0" ixy="0.0" ixz="0.0" iyy="1.0" iyz="0.0" izz="1.0"/>
        </inertial>
        <visual>
            <geometry>
                <box size="0.016346  0.0032815 0.1918488"/>
            </geometry>
            <origin rpy="1.57075 0 1.57075" xyz="0 0 0"/>
            <material name="black"/>
        </visual>
        <collision>
            <geometry>
                <box size="0.016346  0.0032815 0.1918488"/>
            </geometry>
            <origin rpy="1.57075 0 1.57075" xyz="0 0 0"/>
            <material name="black"/>
        </collision>
    </link>

    <gazebo reference="right_track_1">
        <turnGravityOff>false</turnGravityOff>
    </gazebo>

    <link name="right_track_2">
        <inertial>
            <mass value="1"/>
		    <inertia ixx="1.0" ixy="0.0" ixz="0.0" iyy="1.0" iyz="0.0" izz="1.0"/>
        </inertial>
        <visual>
            <geometry>
                <box size="0.016346  0.0032815 0.1918488"/>
            </geometry>
            <origin rpy="1.57075 0 1.57075" xyz="0 0 0"/>
            <material name="black"/>
        </visual>
        <collision>
            <geometry>
                <box size="0.016346  0.0032815 0.1918488"/>
            </geometry>
            <origin rpy="1.57075 0 1.57075" xyz="0 0 0"/>
            <material name="black"/>
        </collision>
   </link>

   <gazebo reference="right_track_2">
        <turnGravityOff>false</turnGravityOff>
    </gazebo>

    <link name="left_track_1">
        <inertial>
            <mass value="1"/>
		    <inertia ixx="1.0" ixy="0.0" ixz="0.0" iyy="1.0" iyz="0.0" izz="1.0"/>
        </inertial>
        <visual>
            <geometry>
                <box size="0.016346  0.0032815 0.1918488"/>
            </geometry>
            <origin rpy="1.57075 0 1.57075" xyz="0 0 0"/>
            <material name="black"/>
        </visual>
        <collision>
            <geometry>
                <box size="0.016346  0.0032815 0.1918488"/>
            </geometry>
            <origin rpy="1.57075 0 1.57075" xyz="0 0 0"/>
            <material name="black"/>
        </collision>
   </link>

   <gazebo reference="left_track_1">
        <turnGravityOff>false</turnGravityOff>
    </gazebo>

   <link name="left_track_2">
        <inertial>
            <mass value="1"/>
		    <inertia ixx="1.0" ixy="0.0" ixz="0.0" iyy="1.0" iyz="0.0" izz="1.0"/>
        </inertial>
        <visual>
            <geometry>
                <box size="0.016346  0.0032815 0.1918488"/>
            </geometry>
            <origin rpy="1.57075 0 1.57075" xyz="0 0 0"/>
            <material name="black"/>
        </visual>
        <collision>
            <geometry>
                <box size="0.016346  0.0032815 0.1918488"/>
            </geometry>
            <origin rpy="1.57075 0 1.57075" xyz="0 0 0"/>
            <material name="black"/>
        </collision>
   </link>

   <gazebo reference="left_track_2">
        <turnGravityOff>false</turnGravityOff>
    </gazebo>

    <link name="wheel_1">
        <inertial>
            <mass value="1"/>
		    <inertia ixx="1.0" ixy="0.0" ixz="0.0" iyy="1.0" iyz="0.0" izz="1.0"/>
        </inertial>
       <visual>
            <geometry>
                <cylinder length="0.016346" radius="0.0445165"/>
            </geometry>
            <origin rpy="1.5709 0 0" xyz="0 0 0"/>
            <material name="black"/>
        </visual>
        <collision>
            <geometry>
                <cylinder length="0.016346" radius="0.0445165"/>
            </geometry>
            <origin rpy="1.5709 0 0" xyz="0 0 0"/>
            <material name="black"/>
        </collision>
   </link>

   <gazebo reference="wheel_1">
        <mu1 value="200.0"/>
  		<mu2 value="100.0"/>
  		<kp value="10000000.0" />
  		<kd value="1.0" />
  		<material>Gazebo/Grey</material>
        <turnGravityOff>false</turnGravityOff>
    </gazebo>

    <link name="wheel_2">
        <inertial>
            <mass value="1"/>
		    <inertia ixx="1.0" ixy="0.0" ixz="0.0" iyy="1.0" iyz="0.0" izz="1.0"/>
        </inertial>
       <visual>
            <geometry>
                <cylinder length="0.016346" radius="0.0445165"/>
            </geometry>
            <origin rpy="1.57095 0 0" xyz="0 0 0"/>
            <material name="black"/>
        </visual>
        <collision>
            <geometry>
                <cylinder length="0.016346" radius="0.0445165"/>
            </geometry>
            <origin rpy="1.57095 0 0" xyz="0 0 0"/>
            <material name="black"/>
        </collision>
   </link>

   <gazebo reference="wheel_2">
        <mu1 value="200.0"/>
  		<mu2 value="100.0"/>
  		<kp value="10000000.0" />
  		<kd value="1.0" />
  		<material>Gazebo/Grey</material>
        <turnGravityOff>false</turnGravityOff>
    </gazebo>

   <link name="wheel_3">
        <inertial>
            <mass value="1"/>
		    <inertia ixx="1.0" ixy="0.0" ixz="0.0" iyy="1.0" iyz="0.0" izz="1.0"/>
        </inertial>
       <visual>
            <geometry>
                <cylinder length="0.016346" radius="0.0445165"/>
            </geometry>
            <origin rpy="1.57095 0 0" xyz="0 0 0"/>
            <material name="black"/>
        </visual>
        <collision>
            <geometry>
                <cylinder length="0.016346" radius="0.0445165"/>
            </geometry>
            <origin rpy="1.57095 0 0" xyz="0 0 0"/>
            <material name="black"/>
        </collision>
   </link>

   <gazebo reference="wheel_3">
        <turnGravityOff>false</turnGravityOff>
    </gazebo>

   <link name="wheel_4">
        <inertial>
            <mass value="1"/>
		    <inertia ixx="1.0" ixy="0.0" ixz="0.0" iyy="1.0" iyz="0.0" izz="1.0"/>
        </inertial>
       <visual>
            <geometry>
                <cylinder length="0.016346" radius="0.0445165"/>
            </geometry>
            <origin rpy="1.57095 0 0" xyz="0 0 0"/>
            <material name="black"/>
        </visual>
        <collision>
            <geometry>
                <cylinder length="0.016346" radius="0.0445165"/>
            </geometry>
            <origin rpy="1.57095 0 0" xyz="0 0 0"/>
            <material name="black"/>
        </collision>
   </link>

   <gazebo reference="wheel_4">
        <turnGravityOff>false</turnGravityOff>
    </gazebo>

    <joint name="base_to_right_track_1" type="fixed">
        <parent link="base_link"/>
        <child link="right_track_1"/>
        <origin xyz="0 0.07 0.008430499999999994"/>
    </joint>

    <joint name="base_to_right_track_2" type="fixed">
        <parent link="base_link"/>
        <child link="right_track_2"/>
        <origin xyz="0 0.07 -0.07956950000000001"/>
    </joint>


  <joint name="base_to_left_track_1" type="fixed">
        <parent link="base_link"/>
        <child link="left_track_1"/>
        <origin xyz="0 -0.07 0.008430499999999994"/>
  </joint>

  <joint name="base_to_left_track_2" type="fixed">
        <parent link="base_link"/>
        <child link="left_track_2"/>
        <origin xyz="0 -0.07 -0.07956950000000001"/>
    </joint>

  <joint name="base_to_wheel_1" type="continuous">
        <parent link="base_link"/>
        <child link="wheel_1"/>
        <origin xyz="0.0959235 0.07 -0.036"/>
        <axis rpy="0  0" xyz="0 1 0"/>
      <limit effort="100" velocity="100"/>
      <joint_properties damping="0.0" friction="0.0"/>
  </joint>

  <joint name="base_to_wheel_2" type="continuous">
        <parent link="base_link"/>
        <child link="wheel_2"/>
        <origin xyz="-0.0959235 0.07 -0.036"/>
        <axis rpy="0  0" xyz="0 1 0"/>
      <limit effort="100" velocity="100"/>
      <joint_properties damping="0.0" friction="0.0"/>
  </joint>

  <joint name="base_to_wheel_3" type="fixed">
        <parent link="base_link"/>
        <child link="wheel_3"/>
        <origin xyz="0.0959235 -0.07 -0.036"/>
  </joint>

  <joint name="base_to_wheel_4" type="fixed">
        <parent link="base_link"/>
        <child link="wheel_4"/>
        <origin xyz="-0.0959235 -0.07 -0.036"/>
  </joint>


  <joint name="base_kinect_joint" type="fixed">
    <origin rpy="0 0 0" xyz="0.105 0 0.043"/>
    <parent link="base_link"/>
    <child link="kinect_link"/>
  </joint>

  <link name="kinect_link">
    <inertial>
      <mass value="0.00001"/>
      <origin xyz="0 0 0"/>
      <inertia ixx="1.0" ixy="0.0" ixz="0.0" iyy="1.0" iyz="0.0" izz="1.0"/>
    </inertial>
    <visual>
      <origin rpy="0 0 0" xyz="0 0 0 "/>
      <geometry>
        <mesh filename="package://traxster/meshes/kinect.dae" scale="73 73 73"/>
      </geometry>
    </visual>
    <collision>
      <origin rpy="0 0 0" xyz="-0.0275 0.0 0.0"/>
      <geometry>
        <box size="0.0730 .2760 0.0720"/>
      </geometry>
    </collision>
  </link>
  <joint name="kinect_depth_joint" type="fixed">
    <origin rpy="0 0 0" xyz="0 0.018 0"/>
    <parent link="kinect_link"/>
    <child link="kinect_depth_frame"/>
  </joint>
  <link name="kinect_depth_frame">
    <inertial>
      <mass value="0.000001"/>
      <origin xyz="0 0 0"/>
      <inertia ixx="0.0001" ixy="0.0" ixz="0.0" iyy="0.0001" iyz="0.0" izz="0.0001"/>
    </inertial>
  </link>
  <joint name="kinect_depth_optical_joint" type="fixed">
    <origin rpy="-1.570795 0 -1.570795" xyz="0 0 0"/>
    <parent link="kinect_depth_frame"/>
    <child link="kinect_depth_optical_frame"/>
  </joint>
  <link name="kinect_depth_optical_frame">
    <inertial>
      <mass value="0.000001"/>
      <origin xyz="0 0 0"/>
      <inertia ixx="0.0001" ixy="0.0" ixz="0.0" iyy="0.0001" iyz="0.0" izz="0.0001"/>
    </inertial>
  </link>
  <joint name="kinect_rgb_joint" type="fixed">
    <origin rpy="0 0 0" xyz="0 -0.005 0"/>
    <parent link="kinect_link"/>
    <child link="kinect_rgb_frame"/>
  </joint>
  <link name="kinect_rgb_frame">
    <inertial>
      <mass value="0.000001"/>
      <origin xyz="0 0 0"/>
      <inertia ixx="0.0001" ixy="0.0" ixz="0.0" iyy="0.0001" iyz="0.0" izz="0.0001"/>
    </inertial>
  </link>
  <joint name="kinect_rgb_optical_joint" type="fixed">
    <origin rpy="-1.570795 0 -1.570795" xyz="0 0 0"/>
    <parent link="kinect_rgb_frame"/>
    <child link="kinect_rgb_optical_frame"/>
  </joint>
  <link name="kinect_rgb_optical_frame">
    <inertial>
      <mass value="0.000001"/>
      <origin xyz="0 0 0"/>
      <inertia ixx="0.0001" ixy="0.0" ixz="0.0" iyy="0.0001" iyz="0.0" izz="0.0001"/>
    </inertial>
  </link>
  <link name="left_eye_link">
    <visual>
      <origin rpy="0 1.57 0" xyz="0 0 0"/>
      <geometry>
        <cylinder length="0.01" radius="0.01"/>
      </geometry>
      <material name="OffWhite"/>
    </visual>
    <collision>
      <origin rpy="0 1.57 0" xyz="0 0 0"/>
      <geometry>
        <cylinder length="0.01" radius="0.01"/>
      </geometry>
    </collision>
    <inertial>
      <mass value="0.00001"/>
      <origin xyz="0 0 0"/>
      <inertia ixx="1.0" ixy="0.0" ixz="0.0" iyy="1.0" iyz="0.0" izz="1.0"/>
    </inertial>
  </link>
  <link name="right_eye_link">
    <visual>
      <origin rpy="0 1.57 0" xyz="0 0 0"/>
      <geometry>
        <cylinder length="0.01" radius="0.01"/>
      </geometry>
      <material name="OffWhite"/>
    </visual>
    <collision>
      <origin rpy="0 1.57 0" xyz="0 0 0"/>
      <geometry>
        <cylinder length="0.01" radius="0.01"/>
      </geometry>
    </collision>
    <inertial>
      <mass value="0.00001"/>
      <origin xyz="0 0 0"/>
      <inertia ixx="1.0" ixy="0.0" ixz="0.0" iyy="1.0" iyz="0.0" izz="1.0"/>
    </inertial>
  </link>
  <joint name="left_eye_joint" type="fixed">
    <parent link="kinect_link"/>
    <child link="left_eye_link"/>
    <origin rpy="0 0 0" xyz="-0.005 0.035 0"/>
  </joint>
  <joint name="right_eye_joint" type="fixed">
    <parent link="kinect_link"/>
    <child link="right_eye_link"/>
    <origin rpy="0 0 0" xyz="-0.005 -0.035 0"/>
  </joint>

  <transmission name="wheel1_control">
  		<type>transmission_interface/SimpleTransmission</type>
  		<actuator name="wheel1_motor">
			<mechanicalReduction>1</mechanicalReduction>
  		</actuator>
  		<joint name="base_to_wheel_1">
			<hardwareInterface>hardware_interface/EffortJointInterface</hardwareInterface>
  		</joint>
	</transmission>
    <transmission name="wheel2_control">
  		<type>transmission_interface/SimpleTransmission</type>
  		<actuator name="wheel2_motor">
			<mechanicalReduction>1</mechanicalReduction>
  		</actuator>
  		<joint name="base_to_wheel_2">
			<hardwareInterface>hardware_interface/EffortJointInterface</hardwareInterface>
  		</joint>
	</transmission>


    <gazebo>
	  <plugin filename="libgazebo_ros_diff_drive.so" name="differential_drive_controller_front">
		<rosDebugLevel>Debug</rosDebugLevel>
		<publishWheelTF>false</publishWheelTF>
		<robotNamespace>/</robotNamespace>
		<publishTf>1</publishTf>
		<publishWheelJointState>false</publishWheelJointState>
		<alwaysOn>true</alwaysOn>
		<updateRate>100.0</updateRate>
		<leftJoint>left_wheel_joint</leftJoint>
		<rightJoint>right_wheel_joint</rightJoint>
		<wheelSeparation>1.5</wheelSeparation>
		<wheelDiameter>0.4</wheelDiameter>
		<broadcastTF>1</broadcastTF>
		<wheelTorque>30</wheelTorque>
		<wheelAcceleration>1.8</wheelAcceleration>
		<commandTopic>cmd_vel</commandTopic>
		<odometryFrame>odom</odometryFrame>
		<odometryTopic>odom</odometryTopic>
		<robotBaseFrame>base_footprint</robotBaseFrame>
	  </plugin>
	</gazebo>
</robot>